<?xml version="1.0"?>
<robot xmlns:xacro="http://www.ros.org/wiki/xacro" >

    <xacro:include filename="inertial_macros.xacro"/>

<!-- These are basic material templates that we need to use then we greate geometries-->
<material name="white">
    <color rgba="1 1 1 1"/>
</material>
<material name="orange">
    <color rgba="1 0.3 0.1 1"/>
</material>
<material name="blue">
    <color rgba="0.2 0.2 1 1"/>
</material>
<material name="black">
    <color rgba="0 0 0 1"/>
</material>

<!--BASE LINK-->
<!--Now we create links (Robotics me padha tha) and LINKS have JOINTS-->
<link name="base_link"> <!--this is the differential link-->
</link>

<joint name="chassis_joint" type="fixed">
    <parent link="base_link"/>
    <child link="chassis"/>
    <!--now the links will coincide but we want the chassis ka link slightly behing-->
    <origin xyz="-0.1 0 0"/>
</joint>


<!--CHASSIS LINK-->
<link name="chassis">
    <visual>
        <origin xyz="0.15 0 0.075"/> <!-- this is bcs initially the link will be at the center and we want it at the back and bottom of the box that we create as chassis-->
        <geometry>
            <box size="0.3 0.3 0.15"/> <!--These are the dimentions of the chassis (visualise karenge)-->
        </geometry>
        <material name="white"/>
    </visual>
    <collision>
        <origin xyz="0.15 0 0.075"/> <!-- this is bcs initially the link will be at the center and we want it at the back and bottom of the box that we create as chassis-->
        <geometry>
            <box size="0.3 0.3 0.15"/> <!--These are the dimentions of the chassis (visualise karenge)-->
        </geometry>
    </collision>
    <xacro:inertial_box mass="0.5" x="0.3" y="0.3" z="0.15">
        <origin xyz="0.15 0 0.075" rpy="0 0 0"/>
    </xacro:inertial_box>
</link>

<!--now we just add gazebo tags that tell gazebo to do certain things while simulation-->
<!--first thing we can tackle is fixin up the colors, basically any link that has a visual tag, we need to add a gazebo tag to add the colors in gazebo during the simulation-->
<gazebo reference="chassis">
    <material>Gazebo/White</material>
</gazebo>

<!-- LEFT WHEEL LINK -->
<joint name="left_wheel_joint" type="continuous">
    <parent link="base_link"/>
    <child link="left_wheel"/>
    <origin xyz="0 0.175 0" rpy="-${pi/2} 0 0"/> <!-- this is bcs generally the z axis of wheel and base might coincide but we want them to be perpendicular as the wheel is vertical-->
    <axis xyz="0 0 1"/>
</joint>

<link name="left_wheel">
    <visual>
        <geometry>
            <cylinder radius="0.05" length="0.04"/>
        </geometry>
        <material name="blue"/>
    </visual>
    <collision>
        <geometry>
            <cylinder radius="0.05" length="0.04"/>
        </geometry>
    </collision>
    <xacro:inertial_cylinder mass="0.1" length="0.04" radius="0.05">
        <origin xyz="0 0 0" rpy="0 0 0"/>
    </xacro:inertial_cylinder>
</link>
<gazebo reference="left_wheel">
    <material>Gazebo/Blue</material>
</gazebo>


<!--RIGHT WHEEL LINK-->
<joint name="right_wheel_joint" type="continuous">
    <parent link="base_link"/>
    <child link="right_wheel"/>
    <origin xyz="0 -0.175 0" rpy="${pi/2} 0 0"/> <!-- this is bcs generally the z axis of wheel and base might coincide but we want them to be perpendicular as the wheel is vertical-->
    <axis xyz="0 0 -1"/>
</joint>

<link name="right_wheel">
    <visual>
        <geometry>
            <cylinder radius="0.05" length="0.04"/>
        </geometry>
        <material name="blue"/>
    </visual>
    <collision>
        <geometry>
            <cylinder radius="0.05" length="0.04"/>
        </geometry>
    </collision>
        <xacro:inertial_cylinder mass="0.1" length="0.04" radius="0.05">
        <origin xyz="0 0 0" rpy="0 0 0"/>
    </xacro:inertial_cylinder>
</link>
<gazebo reference="right_wheel">
    <material>Gazebo/Blue</material>
</gazebo>

<!--CASTER WHEEL LINK-->
<joint name="caster_wheel_joint" type="fixed">
    <parent link="chassis"/>
    <child link="caster_wheel"/>
    <origin xyz="0.24 0 0"/>
</joint>

<link name="caster_wheel">
    <visual>
        <geometry>
            <sphere radius="0.05"/>
        </geometry>
        <material name="black"/>
    </visual>
    <collision>
        <geometry>
            <sphere radius="0.05"/>
        </geometry>
    </collision>
    <xacro:inertial_sphere mass="0.1" radius="0.05">
        <origin xyz="0 0 0" rpy="0 0 0"/>
    </xacro:inertial_sphere>
</link>
<gazebo reference="caster_wheel">
    <material>Gazebo/Black</material>
    <mu1 value="0.0001"/>
    <mu2 value="0.0001"/>
</gazebo>

<!--STEPS TO RUN
1. rebuilt the files : colcon build symlink-install in the dev_ws dir
2. re-run robot state publisher : ros2 launch Diff_Drive_Robot rsp.launch.py


-->

</robot>